<?xml version="1.0" encoding="UTF-8"?>
<!-- Generated by org.testng.reporters.JUnitReportReporter -->
<testsuite hostname="aspire134" name="com.billingcenter.unittest.VerifyAddGetDeleteUser" tests="1" failures="0" timestamp="10 Jan 2012 10:29:20 GMT" time="23.159" errors="1">
  <testcase name="verifyAddGetDeleteUser" time="23.159" classname="com.billingcenter.unittest.VerifyAddGetDeleteUser">
    <error type="java.lang.AssertionError" message="Un expected Exception is occurred; More Details    : Connection timed out: connect">
      <![CDATA[java.lang.AssertionError: Un expected Exception is occurred; More Details    : Connection timed out: connect
	at org.testng.Assert.fail(Assert.java:89)
	at com.billingcenter.unittest.VerifyAddGetDeleteUser.verifyAddGetDeleteUser(VerifyAddGetDeleteUser.java:84)
	at sun.reflect.NativeMethodAccessorImpl.invoke0(Native Method)
	at sun.reflect.NativeMethodAccessorImpl.invoke(Unknown Source)
	at sun.reflect.DelegatingMethodAccessorImpl.invoke(Unknown Source)
	at java.lang.reflect.Method.invoke(Unknown Source)
	at org.testng.internal.MethodInvocationHelper.invokeMethod(MethodInvocationHelper.java:80)
	at org.testng.internal.Invoker.invokeMethod(Invoker.java:691)
	at org.testng.internal.Invoker.invokeTestMethod(Invoker.java:883)
	at org.testng.internal.Invoker.invokeTestMethods(Invoker.java:1208)
	at org.testng.internal.TestMethodWorker.invokeTestMethods(TestMethodWorker.java:127)
	at org.testng.internal.TestMethodWorker.run(TestMethodWorker.java:111)
	at org.testng.TestRunner.privateRun(TestRunner.java:753)
	at org.testng.TestRunner.run(TestRunner.java:613)
	at org.testng.SuiteRunner.runTest(SuiteRunner.java:335)
	at org.testng.SuiteRunner.runSequentially(SuiteRunner.java:330)
	at org.testng.SuiteRunner.privateRun(SuiteRunner.java:292)
	at org.testng.SuiteRunner.run(SuiteRunner.java:241)
	at org.testng.SuiteRunnerWorker.runSuite(SuiteRunnerWorker.java:52)
	at org.testng.SuiteRunnerWorker.run(SuiteRunnerWorker.java:86)
	at org.testng.TestNG.runSuitesSequentially(TestNG.java:1169)
	at org.testng.TestNG.runSuitesLocally(TestNG.java:1094)
	at org.testng.TestNG.run(TestNG.java:1006)
	at org.testng.remote.RemoteTestNG.run(RemoteTestNG.java:107)
	at org.testng.remote.RemoteTestNG.initAndRun(RemoteTestNG.java:199)
	at org.testng.remote.RemoteTestNG.main(RemoteTestNG.java:170)
]]>
    </error>
  </testcase>
</testsuite>
